<?xml version="1.0" ?>
<sdf version="1.8">
    <model name='diff_drive'>

      <link name='chassis'>
        <pose>-0.151427 0 0.175 0 0 0</pose>
        <inertial>
          <mass>1.14395</mass>
          <inertia>
            <ixx>0.126164</ixx>
            <ixy>0</ixy>
            <ixz>0</ixz>
            <iyy>0.416519</iyy>
            <iyz>0</iyz>
            <izz>0.481014</izz>
          </inertia>
        </inertial>
        <visual name='visual_chassis'>
          <geometry>
            <box>
              <size>2.01142 1 0.568726</size>
            </box>
          </geometry>
          <material>
            <ambient>0.5 0.5 1.0 1</ambient>
            <diffuse>0.5 0.5 1.0 1</diffuse>
            <specular>0.0 0.0 1.0 1</specular>
          </material>
        </visual>
        <collision name='collision_chassis'>
          <geometry>
            <box>
              <size>2.01142 1 0.568726</size>
            </box>
          </geometry>
        </collision>
      </link>

      <link name='left_wheel'>
        <pose>0.554283 0.625029 -0.025 -1.5707 0 0</pose>
        <inertial>
          <mass>2</mass>
          <inertia>
            <ixx>0.145833</ixx>
            <ixy>0</ixy>
            <ixz>0</ixz>
            <iyy>0.145833</iyy>
            <iyz>0</iyz>
            <izz>0.125</izz>
          </inertia>
        </inertial>
        <visual name='visual_left_wheel'>
          <geometry>
            <sphere>
              <radius>0.3</radius>
            </sphere>
          </geometry>
          <material>
            <ambient>0.2 0.2 0.2 1</ambient>
            <diffuse>0.2 0.2 0.2 1</diffuse>
            <specular>0.2 0.2 0.2 1</specular>
          </material>
        </visual>
        <collision name='collision_left_wheel'>
          <geometry>
            <sphere>
              <radius>0.3</radius>
            </sphere>
          </geometry>
        </collision>
      </link>

      <link name='right_wheel'>
        <pose>0.554282 -0.625029 -0.025 -1.5707 0 0</pose>
        <inertial>
          <mass>2</mass>
          <inertia>
            <ixx>0.145833</ixx>
            <ixy>0</ixy>
            <ixz>0</ixz>
            <iyy>0.145833</iyy>
            <iyz>0</iyz>
            <izz>0.125</izz>
          </inertia>
        </inertial>
        <visual name='visual_right_wheel'>
          <geometry>
            <sphere>
              <radius>0.3</radius>
            </sphere>
          </geometry>
          <material>
            <ambient>0.2 0.2 0.2 1</ambient>
            <diffuse>0.2 0.2 0.2 1</diffuse>
            <specular>0.2 0.2 0.2 1</specular>
          </material>
        </visual>
        <collision name='collision_right_wheel'>
          <geometry>
            <sphere>
              <radius>0.3</radius>
            </sphere>
          </geometry>
        </collision>
      </link>

      <link name='caster'>
        <pose>-0.957138 0 -0.125 0 0 0</pose>
        <inertial>
          <mass>1</mass>
          <inertia>
            <ixx>0.1</ixx>
            <ixy>0</ixy>
            <ixz>0</ixz>
            <iyy>0.1</iyy>
            <iyz>0</iyz>
            <izz>0.1</izz>
          </inertia>
        </inertial>
        <visual name='visual_caster'>
          <geometry>
            <sphere>
              <radius>0.2</radius>
            </sphere>
          </geometry>
          <material>
            <ambient>0.2 0.2 0.2 1</ambient>
            <diffuse>0.2 0.2 0.2 1</diffuse>
            <specular>0.2 0.2 0.2 1</specular>
          </material>
        </visual>
        <collision name='collision_caster'>
          <geometry>
            <sphere>
              <radius>0.2</radius>
            </sphere>
          </geometry>
        </collision>
      </link>

      <!-- ГОЛОВА -->
      <link name='golova'>
        <pose>1 0 0.8 0 0 0</pose>
        <inertial>
          <mass>0.5</mass>
          <inertia>
            <ixx>0.01</ixx>
            <ixy>0</ixy>
            <ixz>0</ixz>
            <iyy>0.01</iyy>
            <iyz>0</iyz>
            <izz>0.01</izz>
          </inertia>
        </inertial>
        <visual name='visual_golova'>
          <geometry>
            <box>
              <size>1 1 1</size>
            </box>
          </geometry>
          <material>
            <ambient>1.0 0.5 0.5 1</ambient>
            <diffuse>1.0 0.5 0.5 1</diffuse>
            <specular>0.5 0.2 0.2 1</specular>
          </material>
        </visual>
        <collision name='collision_golova'>
          <geometry>
            <box>
              <size>1 1 1</size>
            </box>
          </geometry>
        </collision>
      </link>

      <!-- ДЕКОРАТИВНЫЕ ЭЛЕМЕНТЫ -->
      <link name='yxo1'>
        <pose>1 0.5 1 0 0 0</pose>
        <inertial>
          <mass>0.1</mass>
          <inertia>
            <ixx>0.001</ixx>
            <ixy>0</ixy>
            <ixz>0</ixz>
            <iyy>0.001</iyy>
            <iyz>0</iyz>
            <izz>0.001</izz>
          </inertia>
        </inertial>
        <visual name='visual_yxo1'>
          <geometry>
            <box>
              <size>0.5 0.1 0.5</size>
            </box>
          </geometry>
          <material>
            <ambient>0.0 1.0 0.0 1</ambient>
            <diffuse>0.0 1.0 0.0 1</diffuse>
            <specular>0.0 0.5 0.0 1</specular>
          </material>
        </visual>
        <collision name='collision_yxo1'>
          <geometry>
            <box>
              <size>0.5 0.1 0.5</size>
            </box>
          </geometry>
        </collision>
      </link>

      <link name='yxo2'>
        <pose>1 -0.5 1 0 0 0</pose>
        <inertial>
          <mass>0.1</mass>
          <inertia>
            <ixx>0.001</ixx>
            <ixy>0</ixy>
            <ixz>0</ixz>
            <iyy>0.001</iyy>
            <iyz>0</iyz>
            <izz>0.001</izz>
          </inertia>
        </inertial>
        <visual name='visual_yxo2'>
          <geometry>
            <box>
              <size>0.5 0.1 0.5</size>
            </box>
          </geometry>
          <material>
            <ambient>1.0 1.0 0.0 1</ambient>
            <diffuse>1.0 1.0 0.0 1</diffuse>
            <specular>0.5 0.5 0.0 1</specular>
          </material>
        </visual>
        <collision name='collision_yxo2'>
          <geometry>
            <box>
              <size>0.5 0.1 0.5</size>
            </box>
          </geometry>
        </collision>
      </link>



      <link name='nos'>
        <pose>1.4 0 1 0 0 0</pose>
        <inertial>
          <mass>0.1</mass>
          <inertia>
            <ixx>0.001</ixx>
            <ixy>0</ixy>
            <ixz>0</ixz>
            <iyy>0.001</iyy>
            <iyz>0</iyz>
            <izz>0.001</izz>
          </inertia>
        </inertial>
        <visual name='visual_nos'>
          <geometry>
            <box>
              <size>0.3 0.5 0.2</size>
            </box>
          </geometry>
          <material>
            <ambient>1.0 1.0 0.0 1</ambient>
            <diffuse>1.0 1.0 0.0 1</diffuse>
            <specular>0.5 0.5 0.0 1</specular>
          </material>
        </visual>
        <collision name='collision_nos'>
          <geometry>
            <box>
              <size>0.3 0.5 0.2</size>
            </box>
          </geometry>
        </collision>
      </link>

      <link name='nos2'>
        <pose>1.5 0 1 0 0 0</pose>
        <inertial>
          <mass>0.1</mass>
          <inertia>
            <ixx>0.001</ixx>
            <ixy>0</ixy>
            <ixz>0</ixz>
            <iyy>0.001</iyy>
            <iyz>0</iyz>
            <izz>0.001</izz>
          </inertia>
        </inertial>
        <visual name='visual_nos2'>
          <geometry>
            <box>
              <size>0.1 0.1 0.1</size>
            </box>
          </geometry>
          <material>
            <ambient>1.0 1.0 0.0 1</ambient>
            <diffuse>1.0 1.0 0.0 1</diffuse>
            <specular>0.5 0.5 0.0 1</specular>
          </material>
        </visual>
        <collision name='collision_nos2'>
          <geometry>
            <box>
              <size>0.1 0.1 0.1</size>
            </box>
          </geometry>
        </collision>
      </link>

      <link name='glaza1'>
        <pose>1.5 0.4 1.5 0 0 0</pose>
        <inertial>
          <mass>0.1</mass>
          <inertia>
            <ixx>0.001</ixx>
            <ixy>0</ixy>
            <ixz>0</ixz>
            <iyy>0.001</iyy>
            <iyz>0</iyz>
            <izz>0.001</izz>
          </inertia>
        </inertial>
        <visual name='visual_glaza1'>
          <geometry>
            <box>
              <size>0.1 0.1 0.3</size>
            </box>
          </geometry>
          <material>
            <ambient>1.0 1.0 0.0 1</ambient>
            <diffuse>1.0 1.0 0.0 1</diffuse>
            <specular>0.5 0.5 0.0 1</specular>
          </material>
        </visual>
        <collision name='collision_glaza1'>
          <geometry>
            <box>
              <size>0.1 0.1 0.3</size>
            </box>
          </geometry>
        </collision>
      </link>


      <link name='glaza2'>
        <pose>1.5 0 1.5 0 0 0</pose>
        <inertial>
          <mass>0.1</mass>
          <inertia>
            <ixx>0.001</ixx>
            <ixy>0</ixy>
            <ixz>0</ixz>
            <iyy>0.001</iyy>
            <iyz>0</iyz>
            <izz>0.001</izz>
          </inertia>
        </inertial>
        <visual name='visual_glaza2'>
          <geometry>
            <box>
              <size>0.1 0.1 0.3</size>
            </box>
          </geometry>
          <material>
            <ambient>1.0 1.0 0.0 1</ambient>
            <diffuse>1.0 1.0 0.0 1</diffuse>
            <specular>0.5 0.5 0.0 1</specular>
          </material>
        </visual>
        <collision name='collision_glaza2'>
          <geometry>
            <box>
              <size>0.1 0.1 0.3</size>
            </box>
          </geometry>
        </collision>
      </link>




      <link name="lidar_link">
        <pose>1.8 0 1 0 0 0</pose>
        <inertial>
          <mass>0.1</mass>
          <inertia>
            <ixx>0.000166667</ixx>
            <iyy>0.000166667</iyy>
            <izz>0.000166667</izz>
          </inertia>
        </inertial>
        <collision name="collision">
          <geometry>
            <box>
              <size>0.1 0.1 0.1</size>
            </box>
          </geometry>
        </collision>
        <visual name="visual">
          <geometry>
            <box>
              <size>0.1 0.1 0.1</size>
            </box>
          </geometry>
        </visual>

        <sensor name='lidar' type='gpu_lidar'>
          <pose>0 0 0 0 0 0</pose>
          <topic>scan</topic>
          <frame>lidar_link</frame>

          <ros>
            <!-- Явно указываем frame_id -->
            <frame_id>diff_drive/lidar_link</frame_id>
          </ros>

          <update_rate>10</update_rate>


          <lidar>
            <scan>
              <horizontal>
                <samples>640</samples>
                <resolution>1</resolution>
                <min_angle>-1.396263</min_angle>
                <max_angle>1.396263</max_angle>
              </horizontal>
              <vertical>
                <samples>1</samples>
                <resolution>1</resolution>
                <min_angle>0.0</min_angle>
                <max_angle>0.0</max_angle>
              </vertical>
            </scan>
            <range>
              <min>0.08</min>
              <max>10.0</max>
              <resolution>0.01</resolution>
            </range>
          </lidar>
          <visualize>true</visualize>
        </sensor>
      </link>




      <link name="depth_camera_link">
        <pose>1.8 0 1.2 0 0 0</pose>
        <inertial>
          <mass>0.1</mass>
          <inertia>
            <ixx>0.000166667</ixx>
            <iyy>0.000166667</iyy>
            <izz>0.000166667</izz>
          </inertia>
        </inertial>
        <collision name="collision">
          <geometry>
            <box>
              <size>0.1 0.1 0.1</size>
            </box>
          </geometry>
        </collision>
        <visual name="visual">
          <geometry>
            <box>
              <size>0.1 0.1 0.1</size>
            </box>
          </geometry>
        </visual>

        <sensor name="epth_camera" type="depth_camera">
            <pose>0 0.0175 0.0125 0 0 0</pose>
            <update_rate>6</update_rate>
            <always_on>0</always_on>
            <camera>
              <horizontal_fov>1.51843645</horizontal_fov>
              <image>
                <width>848</width>
                <height>480</height>
                <format>R_FLOAT32</format>
              </image>
              <clip>
                <near>0.1</near>
                <far>10</far>
              </clip>
              <lens>
                <intrinsics>
                  <fx>421.61578369140625</fx>
                  <fy>421.61578369140625</fy>
                  <cx>422.2854309082031</cx>
                  <cy>236.57237243652344</cy>
                  <s>0</s>
                </intrinsics>
              </lens>
            </camera>
        </sensor>
      </link>



      <link name="IMU_link">
        <pose>1.8 0 1.5 0 0 0</pose>
        <inertial>
          <mass>0.1</mass>
          <inertia>
            <ixx>0.000166667</ixx>
            <iyy>0.000166667</iyy>
            <izz>0.000166667</izz>
          </inertia>
        </inertial>
        <collision name="collision">
          <geometry>
            <box>
              <size>0.1 0.1 0.1</size>
            </box>
          </geometry>
        </collision>
        <visual name="visual">
          <geometry>
            <box>
              <size>0.1 0.1 0.1</size>
            </box>
          </geometry>
        </visual>

        <sensor name="imu_sensor" type="imu">
            <always_on>1</always_on>
            <update_rate>1</update_rate>
            <visualize>true</visualize>
            <topic>imu</topic>
            <gz_frame_id>diff_drive/IMU_link</gz_frame_id>
        </sensor>

      </link>

    


      <!-- СУСТАВЫ -->

      <joint name='imu_joint' type='fixed'>
        <parent>chassis</parent>
        <child>IMU_link</child>
      </joint>

      <joint name='camera_joint' type='fixed'>
        <parent>chassis</parent>
        <child>depth_camera_link</child>
      </joint>


      <joint name='lidar_joint' type='fixed'>
        <parent>chassis</parent>
        <child>lidar_link</child>
      </joint>

      <joint name='left_wheel_joint' type='revolute'>
        <parent>chassis</parent>
        <child>left_wheel</child>
        <axis>
          <xyz>0 0 1</xyz>
          <limit>
            <lower>-1e10</lower>
            <upper>1e10</upper>
          </limit>
        </axis>
      </joint>

      <joint name='right_wheel_joint' type='revolute'>
        <parent>chassis</parent>
        <child>right_wheel</child>
        <axis>
          <xyz>0 0 1</xyz>
          <limit>
            <lower>-1e10</lower>
            <upper>1e10</upper>
          </limit>
        </axis>
      </joint>

      <joint name='caster_wheel' type='ball'>
        <parent>chassis</parent>
        <child>caster</child>
      </joint>

      <joint name='golova_joint' type='fixed'>
        <parent>chassis</parent>
        <child>golova</child>
      </joint>

      <joint name='yxo1_joint' type='fixed'>
        <parent>chassis</parent>
        <child>yxo1</child>
      </joint>

      <joint name='nos_joint' type='fixed'>
        <parent>chassis</parent>
        <child>nos</child>
      </joint>

      <joint name='nos2_joint' type='fixed'>
        <parent>chassis</parent>
        <child>nos2</child>
      </joint>

      <joint name='yxo2_joint' type='fixed'>
        <parent>chassis</parent>
        <child>yxo2</child>
      </joint>

      <joint name='glaza1_joint' type='fixed'>
        <parent>golova</parent>
        <child>glaza1</child>
      </joint>

      <joint name='glaza2_joint' type='fixed'>
        <parent>golova</parent>
        <child>glaza2</child>
      </joint>

      <plugin
        filename="ignition-gazebo-diff-drive-system"
        name="ignition::gazebo::systems::DiffDrive">
        <left_joint>left_wheel_joint</left_joint>
        <right_joint>right_wheel_joint</right_joint>
        <wheel_separation>1.25</wheel_separation>
        <wheel_radius>0.3</wheel_radius>
        <odom_publish_frequency>1</odom_publish_frequency>
        <max_linear_acceleration>1</max_linear_acceleration>
        <min_linear_acceleration>-1</min_linear_acceleration>
        <max_angular_acceleration>2</max_angular_acceleration>
        <min_angular_acceleration>-2</min_angular_acceleration>
        <max_linear_velocity>0.5</max_linear_velocity>
        <min_linear_velocity>-0.5</min_linear_velocity>
        <max_angular_velocity>1</max_angular_velocity>
        <min_angular_velocity>-1</min_angular_velocity>
      </plugin>
    </model>
</sdf>