<?xml version="1.0" ?>
<!-- =================================================================================== -->
<!-- |    This document was autogenerated by xacro from sam_bot_description.xacro      | -->
<!-- |    EDITING THIS FILE BY HAND IS NOT RECOMMENDED                                 | -->
<!-- =================================================================================== -->
<robot name="sam_bot">
  <!-- Robot Footprint -->
  <link name="base_footprint">
    <inertial>
      <mass value="0.001"/>
      <inertia ixx="0.001" ixy="0.0" ixz="0.0" iyy="0.001" iyz="0.0" izz="0.001"/>
    </inertial>
  </link>
  <!-- Robot Base -->
  <link name="base_link">
    <visual>
      <geometry>
        <box size="0.42 0.42 0.42"/>
      </geometry>
      <material name="Cyan">
        <color rgba="0 1.0 1.0 1.0"/>
      </material>
    </visual>
    <collision>
      <geometry>
        <box size="0.42 0.42 0.42"/>
      </geometry>
    </collision>
    <inertial>
      <origin rpy="0 0 0" xyz="0 0 0"/>
      <mass value="15"/>
      <inertia ixx="0.44099999999999995" ixy="0.0" ixz="0.0" iyy="0.44099999999999995" iyz="0.0" izz="0.44099999999999995"/>
    </inertial>
  </link>
  <joint name="base_joint" type="fixed">
    <parent link="base_footprint"/>
    <child link="base_link"/>
    <origin rpy="0 0 0" xyz="0.0 0.0 0.28"/>
  </joint>
  <!-- Robot Neck -->
  <link name="neck_link">
    <visual>
      <geometry>
        <box size="0.1 0.1 0.4"/>
      </geometry>
      <material name="Cyan">
        <color rgba="0 1.0 1.0 1.0"/>
      </material>
    </visual>
    <inertial>
      <origin rpy="0 0 0" xyz="0 0 0"/>
      <mass value="15"/>
      <inertia ixx="0.21250000000000005" ixy="0.0" ixz="0.0" iyy="0.025000000000000005" iyz="0.0" izz="0.21250000000000005"/>
    </inertial>
  </link>
  <!-- Robot Eyes Left -->
  <link name="eyes_left_link">
    <visual>
      <geometry>
        <box size="0.42 0.15 0.15"/>
      </geometry>
      <material name="Cyan">
        <color rgba="0 1.0 1.0 1.0"/>
      </material>
    </visual>
    <inertial>
      <origin rpy="0 0 0" xyz="0 0 0"/>
      <mass value="15"/>
      <inertia ixx="0.24862499999999996" ixy="0.0" ixz="0.0" iyy="0.24862499999999996" iyz="0.0" izz="0.056249999999999994"/>
    </inertial>
  </link>
  <!-- Robot Eyes Right -->
  <link name="eyes_right_link">
    <visual>
      <geometry>
        <box size="0.42 0.15 0.15"/>
      </geometry>
      <material name="Cyan">
        <color rgba="0 1.0 1.0 1.0"/>
      </material>
    </visual>
    <inertial>
      <origin rpy="0 0 0" xyz="0 0 0"/>
      <mass value="15"/>
      <inertia ixx="0.24862499999999996" ixy="0.0" ixz="0.0" iyy="0.24862499999999996" iyz="0.0" izz="0.056249999999999994"/>
    </inertial>
  </link>
  <!-- neck Footprint -->
  <joint name="neck_joint" type="fixed">
    <parent link="base_link"/>
    <child link="neck_link"/>
    <origin rpy="0 0 0" xyz="0.0 0.0 0.31999999999999995"/>
  </joint>
  <!-- Eyes Right Footprint -->
  <joint name="eyes_left_joint" type="fixed">
    <parent link="neck_link"/>
    <child link="eyes_left_link"/>
    <origin rpy="0 0 0" xyz="0.0 -0.13 0.1"/>
  </joint>
  <!-- Eyes Right Footprint -->
  <joint name="eyes_right_joint" type="fixed">
    <parent link="neck_link"/>
    <child link="eyes_right_link"/>
    <origin rpy="0 0 0" xyz="0.0 0.13 0.1"/>
  </joint>
  <link name="drivewhl_l_link">
    <visual>
      <origin rpy="1.5707963267948966 0 0" xyz="0 0 0"/>
      <geometry>
        <cylinder length="0.04" radius="0.1"/>
      </geometry>
      <material name="Gray">
        <color rgba="0.5 0.5 0.5 1.0"/>
      </material>
    </visual>
    <collision>
      <origin rpy="1.5707963267948966 0 0" xyz="0 0 0"/>
      <geometry>
        <cylinder length="0.04" radius="0.1"/>
      </geometry>
    </collision>
    <inertial>
      <origin rpy="0 0 0" xyz="0 0 0"/>
      <mass value="0.5"/>
      <inertia ixx="0.0013166666666666667" ixy="0.0" ixz="0.0" iyy="0.0013166666666666667" iyz="0.0" izz="0.0025000000000000005"/>
    </inertial>
  </link>
  <joint name="drivewhl_l_joint" type="continuous">
    <parent link="base_link"/>
    <child link="drivewhl_l_link"/>
    <origin rpy="0 0 0" xyz="-0.12 0.235 -0.18"/>
    <axis xyz="0 1 0"/>
  </joint>
  <link name="drivewhl_r_link">
    <visual>
      <origin rpy="1.5707963267948966 0 0" xyz="0 0 0"/>
      <geometry>
        <cylinder length="0.04" radius="0.1"/>
      </geometry>
      <material name="Gray">
        <color rgba="0.5 0.5 0.5 1.0"/>
      </material>
    </visual>
    <collision>
      <origin rpy="1.5707963267948966 0 0" xyz="0 0 0"/>
      <geometry>
        <cylinder length="0.04" radius="0.1"/>
      </geometry>
    </collision>
    <inertial>
      <origin rpy="0 0 0" xyz="0 0 0"/>
      <mass value="0.5"/>
      <inertia ixx="0.0013166666666666667" ixy="0.0" ixz="0.0" iyy="0.0013166666666666667" iyz="0.0" izz="0.0025000000000000005"/>
    </inertial>
  </link>
  <joint name="drivewhl_r_joint" type="continuous">
    <parent link="base_link"/>
    <child link="drivewhl_r_link"/>
    <origin rpy="0 0 0" xyz="-0.12 -0.235 -0.18"/>
    <axis xyz="0 1 0"/>
  </joint>
  <!-- Caster Wheel -->
  <link name="front_caster">
    <visual>
      <geometry>
        <sphere radius="0.07000000000000003"/>
      </geometry>
      <material name="Cyan">
        <color rgba="0 1.0 1.0 1.0"/>
      </material>
    </visual>
    <collision>
      <geometry>
        <sphere radius="0.07000000000000003"/>
      </geometry>
    </collision>
    <inertial>
      <mass value="0.5"/>
      <inertia ixx="0.000980000000000001" ixy="0.0" ixz="0.0" iyy="0.000980000000000001" iyz="0.0" izz="0.000980000000000001"/>
    </inertial>
  </link>
  <joint name="caster_joint" type="fixed">
    <parent link="base_link"/>
    <child link="front_caster"/>
    <origin rpy="0 0 0" xyz="0.14 0.0 -0.21"/>
  </joint>
  <!-- ZRACHKI -->
  <!-- Robot ZRACHKI Eyes Left -->
  <link name="zrachki_eyes_left_link">
    <visual>
      <geometry>
        <box size="0.42 0.075 0.075"/>
      </geometry>
      <material name="Cyan">
        <color rgba="0 0.0 0.0 0.0"/>
      </material>
    </visual>
    <inertial>
      <origin rpy="0 0 0" xyz="0 0 0"/>
      <mass value="15"/>
      <inertia ixx="0.22753124999999996" ixy="0.0" ixz="0.0" iyy="0.22753124999999996" iyz="0.0" izz="0.014062499999999999"/>
    </inertial>
  </link>
  <!-- Robot ZRACHKI Eyes Right -->
  <link name="zrachki_eyes_right_link">
    <visual>
      <geometry>
        <box size="0.42 0.075 0.075"/>
      </geometry>
      <material name="Cyan">
        <color rgba="0 0.0 0.0 0.0"/>
      </material>
    </visual>
    <inertial>
      <origin rpy="0 0 0" xyz="0 0 0"/>
      <mass value="15"/>
      <inertia ixx="0.22753124999999996" ixy="0.0" ixz="0.0" iyy="0.22753124999999996" iyz="0.0" izz="0.014062499999999999"/>
    </inertial>
  </link>
  <!-- EZRACHKI yes Right Footprint -->
  <joint name="zrachki_eyes_left_joint" type="fixed">
    <parent link="eyes_left_link"/>
    <child link="zrachki_eyes_left_link"/>
    <origin rpy="0 0 0" xyz="-0.01 0.0 0.0"/>
  </joint>
  <!-- ZRACHKI Eyes Right Footprint -->
  <joint name="zrachki_eyes_right_joint" type="fixed">
    <parent link="eyes_right_link"/>
    <child link="zrachki_eyes_right_link"/>
    <origin rpy="0 0 0" xyz="-0.01 0.0 0.0"/>
  </joint>
</robot>
